Workbook

Sheet Sheet1
A1: start | B1: 45455
A2: end | B2: 45544
A4: \\masterPi\wwl:South:WES8617B_REALTMMETFLO | H4: {=_xll.PIAdvCalcDat(Sheet1!$A$4,Sheet1!$B$1,Sheet1!$B$2,"1h","average (time-weighted)","time-weighted",0,1,65,"")} -> 45455 | I4: 1417.3818 | J4: =I4*(1440/1000000) -> 2.0410298
H5: 45455.042 | I5: 1254.9773 | J5: =I5*(1440/1000000) -> 1.8071674
H6: 45455.083 | I6: 1034.4746 | J6: =I6*(1440/1000000) -> 1.4896435
H7: 45455.125 | I7: 995.37452 | J7: =I7*(1440/1000000) -> 1.4333393
H8: 45455.167 | I8: 1002.7581 | J8: =I8*(1440/1000000) -> 1.4439717
H9: 45455.208 | I9: 1058.4585 | J9: =I9*(1440/1000000) -> 1.5241802
H10: 45455.25 | I10: 1379.4794 | J10: =I10*(1440/1000000) -> 1.9864504
H11: 45455.292 | I11: 1674.8722 | J11: =I11*(1440/1000000) -> 2.411816
H12: 45455.333 | I12: 2007.0317 | J12: =I12*(1440/1000000) -> 2.8901257
H13: 45455.375 | I13: 1984.0928 | J13: =I13*(1440/1000000) -> 2.8570936
H14: 45455.417 | I14: 2182.5228 | J14: =I14*(1440/1000000) -> 3.1428328
H15: 45455.458 | I15: 2233.1167 | J15: =I15*(1440/1000000) -> 3.2156881
H16: 45455.5 | I16: 2263.2881 | J16: =I16*(1440/1000000) -> 3.2591349
... H31: 45456.125 | I31: 955.61889 | J31: =I31*(1440/1000000) -> 1.3760912
H32: 45456.167 | I32: 972.42616
H33: 45456.208 | I33: 1043.4758
H34: 45456.25 | I34: 1435.8798
H35: 45456.292 | I35: 1729.7684
H36: 45456.333 | I36: 1925.2834
H37: 45456.375 | I37: 1981.3469
H38: 45456.417 | I38: 2115.3743
H39: 45456.458 | I39: 2066.6303
H40: 45456.5 | I40: 2252.3442
H41: 45456.542 | I41: 2139.6322
H42: 45456.583 | I42: 2254.923
H43: 45456.625 | I43: 2117.8518
... H280: 45466.5 | I280: 1819.7006
H281: 45466.542 | I281: [-11059] No Good Data For Calculation
H282: 45466.583 | I282: 2344.919
H283: 45466.625 | I283: 2346.4075
H284: 45466.667 | I284: 2126.4552
H285: 45466.708 | I285: 2188.3703
H286: 45466.75 | I286: 2308.3971
H287: 45466.792 | I287: 2294.5558
H288: 45466.833 | I288: 2374.7626
H289: 45466.875 | I289: 2425.2193
H290: 45466.917 | I290: 2204.598
H291: 45466.958 | I291: 1942.1249
...

Sheet Sheet2
A1: start | B1: 45455
A2: end | B2: 45544 | I2: Sampled 15 minutes | N2: Calculated 1 hour average | S2: Current Value 1-hour average
A4: \\masterPi\wwl:South:WES8617B_REALTMMETFLO | H4: {=_xll.PISampDat(Sheet2!$A$4,Sheet2!$B$1,Sheet2!$B$2,"15m",1,"")} -> 45455 | I4: 3772.9163 | M4: {=_xll.PIAdvCalcDat(Sheet2!$A$4,Sheet2!$B$1,Sheet2!$B$2,"1h","average (time-weighted)","time-weighted",0,1,193,"")} -> 45455 | N4: 45455.042 | O4: 1417.3818 | P4: =O4*(1440/1000000) -> 2.0410298 | U4: {=_xll.PIAdvCalcDat(Sheet2!$A$4,"*-1h","*","1h","average (time-weighted)","time-weighted",0,1,193,"")} -> 46125.536 | V4: 46125.578 | W4: 2085.985
H5: 45455.01 | I5: 1823.106 | M5: 45455.042 | N5: 45455.083 | O5: 1254.9773 | P5: =O5*(1440/1000000) -> 1.8071674 | V5: {=_xll.PICurrVal(Sheet2!$A$4,1,"")} -> 46125.58 | W5: 3050.5012
H6: 45455.021 | I6: 3657.4194 | M6: 45455.083 | N6: 45455.125 | O6: 1034.4746 | P6: =O6*(1440/1000000) -> 1.4896435
H7: 45455.031 | I7: 1343.7606 | M7: 45455.125 | N7: 45455.167 | O7: 995.37452 | P7: =O7*(1440/1000000) -> 1.4333393
H8: 45455.042 | I8: 2268.0332 | J8: =(I8+I7+I6+I5)/4 -> 2273.0798 | K8: =J8*(1440/1000000) -> 3.2732349 | M8: 45455.167 | N8: 45455.208 | O8: 1002.7581 | P8: =O8*(1440/1000000) -> 1.4439717
H9: 45455.052 | I9: 2461.6641 | J9: =(I9+I8+I7+I6)/4 -> 2432.7193 | K9: =J9*(1440/1000000) -> 3.5031158 | M9: 45455.208 | N9: 45455.25 | O9: 1058.4585 | P9: =O9*(1440/1000000) -> 1.5241802
H10: 45455.062 | I10: 28.626791 | J10: =(I10+I9+I8+I7)/4 -> 1525.5212 | K10: =J10*(1440/1000000) -> 2.1967505 | M10: 45455.25 | N10: 45455.292 | O10: 1379.4794 | P10: =O10*(1440/1000000) -> 1.9864504
H11: 45455.073 | I11: 0 | J11: =(I11+I10+I9+I8)/4 -> 1189.581 | K11: =J11*(1440/1000000) -> 1.7129967 | M11: 45455.292 | N11: 45455.333 | O11: 1674.8722 | P11: =O11*(1440/1000000) -> 2.411816
H12: 45455.083 | I12: 38.714905 | J12: =(I12+I11+I10+I9)/4 -> 632.25144 | K12: =J12*(1440/1000000) -> 0.91044207 | M12: 45455.333 | N12: 45455.375 | O12: 2007.0317 | P12: =O12*(1440/1000000) -> 2.8901257
H13: 45455.094 | I13: 0 | J13: =(I13+I12+I11+I10)/4 -> 16.835424 | K13: =J13*(1440/1000000) -> 0.02424301 | M13: 45455.375 | N13: 45455.417 | O13: 1984.0928 | P13: =O13*(1440/1000000) -> 2.8570936
H14: 45455.104 | I14: 2295.8442 | J14: =(I14+I13+I12+I11)/4 -> 583.63979 | K14: =J14*(1440/1000000) -> 0.84044129 | M14: 45455.417 | N14: 45455.458 | O14: 2182.5228 | P14: =O14*(1440/1000000) -> 3.1428328
H15: 45455.115 | I15: 1991.9366 | J15: =(I15+I14+I13+I12)/4 -> 1081.6239 | K15: =J15*(1440/1000000) -> 1.5575385 | M15: 45455.458 | N15: 45455.5 | O15: 2233.1167 | P15: =O15*(1440/1000000) -> 3.2156881
H16: 45455.125 | I16: 0.54103386 | J16: =(I16+I15+I14+I13)/4 -> 1072.0805 | K16: =J16*(1440/1000000) -> 1.5437959 | M16: 45455.5 | N16: 45455.542 | O16: 2263.2881 | P16: =O16*(1440/1000000) -> 3.2591349
H17: 45455.135 | I17: 1400.6115 | J17: =(I17+I16+I15+I14)/4 -> 1422.2333 | K17: =J17*(1440/1000000) -> 2.048016 | M17: 45455.542 | N17: 45455.583 | O17: 2198.1024 | P17: =O17*(1440/1000000) -> 3.1652674
H18: 45455.146 | I18: 1258.0304 | J18: =(I18+I17+I16+I15)/4 -> 1162.7799 | K18: =J18*(1440/1000000) -> 1.674403 | M18: 45455.583 | N18: 45455.625 | O18: 2184.0519 | P18: =O18*(1440/1000000) -> 3.1450348
H19: 45455.156 | I19: 1494.7804 | J19: =(I19+I18+I17+I16)/4 -> 1038.4908 | K19: =J19*(1440/1000000) -> 1.4954268 | M19: 45455.625 | N19: 45455.667 | O19: 2198.2721 | P19: =O19*(1440/1000000) -> 3.1655118
H20: 45455.167 | I20: 0 | M20: 45455.667 | N20: 45455.708 | O20: 2029.6145 | P20: =O20*(1440/1000000) -> 2.9226449
H21: 45455.177 | I21: 1272.6165 | M21: 45455.708 | N21: 45455.75 | O21: 2238.655 | P21: =O21*(1440/1000000) -> 3.2236633
H22: 45455.188 | I22: 1833.8495 | M22: 45455.75 | N22: 45455.792 | O22: 2185.4356 | P22: =O22*(1440/1000000) -> 3.1470272
H23: 45455.198 | I23: 1800.8181 | M23: 45455.792 | N23: 45455.833 | O23: 2422.205 | P23: =O23*(1440/1000000) -> 3.4879751
H24: 45455.208 | I24: 1282.5001 | M24: 45455.833 | N24: 45455.875 | O24: 2333.3513 | P24: =O24*(1440/1000000) -> 3.3600258
H25: 45455.219 | I25: 2611.8799 | M25: 45455.875 | N25: 45455.917 | O25: 2423.712 | P25: =O25*(1440/1000000) -> 3.4901452
H26: 45455.229 | I26: 0 | M26: 45455.917 | N26: 45455.958 | O26: 2136.5305 | P26: =O26*(1440/1000000) -> 3.0766039
H27: 45455.24 | I27: 2038.9991 | M27: 45455.958 | N27: 45456 | O27: 1945.371 | P27: =O27*(1440/1000000) -> 2.8013342
H28: 45455.25 | I28: 5.8025522 | M28: 45456 | N28: 45456.042 | O28: 1413.0528 | P28: =O28*(1440/1000000) -> 2.034796
H29: 45455.26 | I29: 3364.928 | M29: 45456.042 | N29: 45456.083 | O29: 1234.4417 | P29: =O29*(1440/1000000) -> 1.777596
H30: 45455.271 | I30: 6.4128594 | M30: 45456.083 | N30: 45456.125 | O30: 1001.9428 | P30: =O30*(1440/1000000) -> 1.4427977
H31: 45455.281 | I31: 3031.1316 | M31: 45456.125 | N31: 45456.167 | O31: 955.61889 | P31: =O31*(1440/1000000) -> 1.3760912
... H42: 45455.396 | I42: 2431.8469 | M42: 45456.583 | N42: 45456.625 | O42: 2254.923 | P42: =O42*(1440/1000000) -> 3.2470891
H43: 45455.406 | I43: I/O Timeout | M43: 45456.625 | N43: 45456.667 | O43: 2117.8518 | P43: =O43*(1440/1000000) -> 3.0497066
H44: 45455.417 | I44: I/O Timeout | M44: 45456.667 | N44: 45456.708 | O44: 2108.2195 | P44: =O44*(1440/1000000) -> 3.035836
H45: 45455.427 | I45: 2730.2983 | M45: 45456.708 | N45: 45456.75 | O45: 2278.3336 | P45: =O45*(1440/1000000) -> 3.2808004
H46: 45455.438 | I46: 2306.4631 | M46: 45456.75 | N46: 45456.792 | O46: 2255.1592
H47: 45455.448 | I47: 2585.3896 | M47: 45456.792 | N47: 45456.833 | O47: 2360.3067
H48: 45455.458 | I48: 3113.501 | M48: 45456.833 | N48: 45456.875 | O48: 2448.135
H49: 45455.469 | I49: 1993.1106 | M49: 45456.875 | N49: 45456.917 | O49: 2328.013
H50: 45455.479 | I50: 2035.3921 | M50: 45456.917 | N50: 45456.958 | O50: 2209.1938
H51: 45455.49 | I51: 2979.2729 | M51: 45456.958 | N51: 45457 | O51: 2012.4176
...
