Workbook

Sheet final-->

Sheet combined
A1: Asset ID | B1: Location Address | C1: JEA GIS Object ID | D1: Sewer Maintenance District | E1: County | F1: Best Estimate of Install Date of Station | G1: Year of Install | H1: Electrical Supplier | I1: JEA Actual ADF (GPD) | J1: JEA Design PHF (GPM) | K1: PS Class
A2: BPS-000639 | B2: 2740 CR 210 | C2: 205269 | D2: St Johns Grid | E2: St Johns | F2: 42676 | G2: =F2 -> 42676 | H2: JEA | I2: =MAX(original!I2,piwebapi_edit!I2,car_edit!I2) -> 2861084.5 | J2: =MAX(original!J2,piwebapi_edit!J2,car_edit!J2) -> 7000
A3: BPS-001645 | B3: 4193 OLDFIELD CROSSING | C3: 1729 | D3: South Grid | E3: Duval | F3: 42755 | G3: =F3 -> 42755 | H3: JEA | I3: =MAX(original!I3,piwebapi_edit!I3,car_edit!I3) -> 2714538.5 | J3: =MAX(original!J3,piwebapi_edit!J3,car_edit!J3) -> 9370
A4: BPS-001950 | B4: 4241 SAN CLERC | C4: 16966 | D4: South Grid | E4: Duval | F4: 41143 | G4: =F4 -> 41143 | H4: JEA | I4: =MAX(original!I4,piwebapi_edit!I4,car_edit!I4) -> 932000 | J4: =MAX(original!J4,piwebapi_edit!J4,car_edit!J4) -> 3040
A5: BPS-002867 | B5: 8617 WESTERN WAY | C5: 204646 | D5: South Grid | E5: Duval | F5: 38533 | G5: =F5 -> 38533 | H5: JEA | I5: =MAX(original!I5,piwebapi_edit!I5,car_edit!I5) -> 2827540.5 | J5: =MAX(original!J5,piwebapi_edit!J5,car_edit!J5) -> 5000
A6: BPS-003387 | B6: 106 TWIN CREEKS Dr | C6: 55153 | D6: St Johns Grid | E6: Duval | F6: 39420 | G6: =F6 -> 39420 | H6: JEA | I6: =MAX(original!I6,piwebapi_edit!I6,car_edit!I6) -> 2481327.6 | J6: =MAX(original!J6,piwebapi_edit!J6,car_edit!J6) -> 4400
A7: BPS-004153 | B7: 6850 Energy Center Drive | C7: 256468 | D7: South Grid | E7: Duval | F7: 43635 | G7: =F7 -> 43635 | H7: JEA | I7: =MAX(original!I7,piwebapi_edit!I7,car_edit!I7) -> 166464 | J7: =MAX(original!J7,piwebapi_edit!J7,car_edit!J7) -> 1200
A8: BPS-004187 | B8: 7806 RAMPART RD | C8: 277052 | D8: West Grid | E8: Duval | F8: 44197 | G8: =F8 -> 44197 | H8: JEA | I8: =MAX(original!I8,piwebapi_edit!I8,car_edit!I8) -> 2297937.6 | J8: =MAX(original!J8,piwebapi_edit!J8,car_edit!J8) -> 5000
A9: BPS-004228 | B9: 10477 BRADLEY RD BOOSTER | C9: 1329 | D9: East Grid | E9: Duval | F9: 44319 | G9: =F9 -> 44319 | H9: JEA | I9: =MAX(original!I9,piwebapi_edit!I9,car_edit!I9) -> 12497059 | J9: =MAX(original!J9,piwebapi_edit!J9,car_edit!J9) -> 19500
A10: BPS-004296 | B10: 3742 ROBENA ROAD | C10: 315233 | D10: North Grid | E10: Duval | F10: 45078 | G10: =F10 -> 45078 | H10: JEA | I10: =MAX(original!I10,piwebapi_edit!I10,car_edit!I10) -> 0 | J10: =MAX(original!J10,piwebapi_edit!J10,car_edit!J10) -> 0
A11: BPS-004333 | B11: 85008 ART WILSON LN | C11: 354434 | D11: Nassau Grid | E11: Nassau | F11: 45350 | G11: =F11 -> 45350 | H11: FPL | I11: =MAX(original!I11,piwebapi_edit!I11,car_edit!I11) -> 0 | J11: =MAX(original!J11,piwebapi_edit!J11,car_edit!J11) -> 0
A12: LS-000001 | B12: 12770 1ST ST | C12: 1907 | D12: North Grid | E12: Duval | F12: 25569 | G12: =F12 -> 25569 | H12: JEA | I12: =MAX(original!I12,piwebapi_edit!I12,car_edit!I12) -> 3800.0027 | J12: =MAX(original!J12,piwebapi_edit!J12,car_edit!J12) -> 391.9503
A13: LS-000002 | B13: 2580 1ST ST W | C13: 54481 | D13: North Grid | E13: Duval | F13: 18264 | G13: =F13 -> 18264 | H13: JEA | I13: =MAX(original!I13,piwebapi_edit!I13,car_edit!I13) -> 772.33629 | J13: =MAX(original!J13,piwebapi_edit!J13,car_edit!J13) -> 178.69535
... A1609: LS-004320 | B1609: 1661 RIBAULT SCENIC DRI | C1609: 338033 | D1609: North Grid | E1609: Duval | F1609: 45186 | G1609: =F1609 -> 45186 | H1609: JEA | I1609: =MAX(original!I1609,piwebapi_edit!I1609,car_edit!I1609) -> 0 | J1609: =MAX(original!J1609,piwebapi_edit!J1609,car_edit!J1609) -> 0
A1610: LS-004321 | B1610: 280 Accolade Av | C1610: 338433 | D1610: St Johns Grid | F1610: 45200 | G1610: =F1610 -> 45200 | H1610: FPL | I1610: =MAX(original!I1610,piwebapi_edit!I1610,car_edit!I1610) -> 863.76843 | J1610: =MAX(original!J1610,piwebapi_edit!J1610,car_edit!J1610) -> 249.89378
A1611: LS-004322 | B1611: 8518 BELFORT LANDING | C1611: 340433 | D1611: South Grid | E1611: Duval | F1611: 45202 | G1611: =F1611 -> 45202 | H1611: JEA | I1611: =MAX(original!I1611,piwebapi_edit!I1611,car_edit!I1611) -> 0 | J1611: =MAX(original!J1611,piwebapi_edit!J1611,car_edit!J1611) -> 0
A1612: LS-004323 | B1612: 442 Palm Valley Rd | C1612: 340033 | D1612: St Johns Grid | E1612: St Johns | F1612: 45108 | G1612: =F1612 -> 45108 | H1612: JEA | I1612: =MAX(original!I1612,piwebapi_edit!I1612,car_edit!I1612) -> 1474.8918 | J1612: =MAX(original!J1612,piwebapi_edit!J1612,car_edit!J1612) -> 185.87591
A1613: LS-004324 | B1613: 6811 Myrtle Oaks Road | C1613: 342833 | D1613: North Grid | E1613: Duval | F1613: 45230 | G1613: =F1613 -> 45230 | H1613: JEA | I1613: =MAX(original!I1613,piwebapi_edit!I1613,car_edit!I1613) -> 0 | J1613: =MAX(original!J1613,piwebapi_edit!J1613,car_edit!J1613) -> 0
A1614: LS-004325 | B1614: 12706 WHELAN AVENUE | C1614: 343233 | D1614: North Grid | E1614: Duval | F1614: 45230 | G1614: =F1614 -> 45230 | H1614: JEA | I1614: =MAX(original!I1614,piwebapi_edit!I1614,car_edit!I1614) -> 0 | J1614: =MAX(original!J1614,piwebapi_edit!J1614,car_edit!J1614) -> 0
A1615: LS-004326 | B1615: 10450 BENSON LAKE DR | C1615: 322833 | D1615: West Grid | E1615: Duval | F1615: 45231 | G1615: =F1615 -> 45231 | H1615: JEA | I1615: =MAX(original!I1615,piwebapi_edit!I1615,car_edit!I1615) -> 0 | J1615: =MAX(original!J1615,piwebapi_edit!J1615,car_edit!J1615) -> 0
A1616: LS-004327 | B1616: 4640 Lusso Lane | D1616: East Grid | E1616: Duval | F1616: 45266 | G1616: =F1616 -> 45266 | H1616: JEA | I1616: =MAX(original!I1616,piwebapi_edit!I1616,car_edit!I1616) -> 0 | J1616: =MAX(original!J1616,piwebapi_edit!J1616,car_edit!J1616) -> 0
A1617: LS-004328 | B1617: 98 Bay Lake Drive | C1617: 345634 | D1617: St Johns Grid | E1617: St Johns | F1617: 45258 | G1617: =F1617 -> 45258 | H1617: FPL | I1617: =MAX(original!I1617,piwebapi_edit!I1617,car_edit!I1617) -> 0 | J1617: =MAX(original!J1617,piwebapi_edit!J1617,car_edit!J1617) -> 0
A1618: LS-004329 | B1618: 12607 Percy Creek Drive | C1618: 345234 | D1618: North Grid | E1618: Duval | F1618: 45279 | G1618: =F1618 -> 45279 | H1618: JEA | I1618: =MAX(original!I1618,piwebapi_edit!I1618,car_edit!I1618) -> 0 | J1618: =MAX(original!J1618,piwebapi_edit!J1618,car_edit!J1618) -> 0
A1619: LS-004330 | B1619: 1015 EAST PEYTON PARKWAY | C1619: 346835 | D1619: St Johns Grid | E1619: Duval | F1619: 45372 | G1619: =F1619 -> 45372 | H1619: JEA | I1619: =MAX(original!I1619,piwebapi_edit!I1619,car_edit!I1619) -> 0 | J1619: =MAX(original!J1619,piwebapi_edit!J1619,car_edit!J1619) -> 0
A1620: LS-004331 | B1620: 5420 Tellaro Lane | C1620: 347634 | D1620: West Grid | E1620: Duval | F1620: 45275 | G1620: =F1620 -> 45275 | H1620: JEA | I1620: =MAX(original!I1620,piwebapi_edit!I1620,car_edit!I1620) -> 0 | J1620: =MAX(original!J1620,piwebapi_edit!J1620,car_edit!J1620) -> 0
A1621: LS-004332 | B1621: 6804 Golden Monarch Avenue | C1621: 347635 | D1621: South Grid | E1621: Duval | F1621: 44913 | G1621: =F1621 -> 44913 | H1621: JEA | I1621: =MAX(original!I1621,piwebapi_edit!I1621,car_edit!I1621) -> 0 | J1621: =MAX(original!J1621,piwebapi_edit!J1621,car_edit!J1621) -> 0
A1622: LS-004334 | B1622: 12273 PARKLAND VIEW LANE | C1622: 348434 | D1622: North Grid | E1622: Duval | F1622: 45302 | G1622: =F1622 -> 45302 | H1622: JEA | I1622: =MAX(original!I1622,piwebapi_edit!I1622,car_edit!I1622) -> 0 | J1622: =MAX(original!J1622,piwebapi_edit!J1622,car_edit!J1622) -> 0
A1623: LS-004335 | B1623: 118 PINE CHASE WAY | C1623: 351235 | D1623: St Johns Grid | E1623: St Johns | F1623: 45300 | G1623: =F1623 -> 45300 | H1623: FPL | I1623: =MAX(original!I1623,piwebapi_edit!I1623,car_edit!I1623) -> 0 | J1623: =MAX(original!J1623,piwebapi_edit!J1623,car_edit!J1623) -> 0
A1624: LS-004336 | B1624: 5425 BARTRAM COMMONS DRIVE | C1624: 349234 | D1624: St Johns Grid | E1624: Duval | F1624: 45300 | G1624: =F1624 -> 45300 | H1624: JEA | I1624: =MAX(original!I1624,piwebapi_edit!I1624,car_edit!I1624) -> 0 | J1624: =MAX(original!J1624,piwebapi_edit!J1624,car_edit!J1624) -> 0
A1625: LS-004337 | B1625: 127 SEAPORT BREEZE ROAD | C1625: 349235 | D1625: St Johns Grid | E1625: St Johns | F1625: 45293 | G1625: =F1625 -> 45293 | H1625: JEA | I1625: =MAX(original!I1625,piwebapi_edit!I1625,car_edit!I1625) -> 28658.524 | J1625: =MAX(original!J1625,piwebapi_edit!J1625,car_edit!J1625) -> 265.58975
A1626: LS-004338 | B1626: 5825 ROBITZSCH LANE | C1626: 354435 | D1626: West Grid | E1626: Duval | F1626: 45303 | G1626: =F1626 -> 45303 | H1626: JEA | I1626: =MAX(original!I1626,piwebapi_edit!I1626,car_edit!I1626) -> 0 | J1626: =MAX(original!J1626,piwebapi_edit!J1626,car_edit!J1626) -> 0
A1627: LS-004339 | B1627: 34 OAK PARK DRIVE | C1627: 351234 | D1627: St Johns Grid | E1627: St Johns | F1627: 45308 | G1627: =F1627 -> 45308 | H1627: FPL | I1627: =MAX(original!I1627,piwebapi_edit!I1627,car_edit!I1627) -> 0 | J1627: =MAX(original!J1627,piwebapi_edit!J1627,car_edit!J1627) -> 0
A1628: LS-004340 | B1628: 9375 LATIGIO LANE | C1628: 350834 | D1628: West Grid | E1628: Duval | F1628: 45317 | G1628: =F1628 -> 45317 | H1628: JEA | I1628: =MAX(original!I1628,piwebapi_edit!I1628,car_edit!I1628) -> 0 | J1628: =MAX(original!J1628,piwebapi_edit!J1628,car_edit!J1628) -> 0
... A1674: VAC-000005 | B1674: 1108 BARNWELL RD | C1674: 72143 | D1674: Nassau Grid | E1674: Nassau | F1674: 38931 | G1674: =F1674 -> 38931 | H1674: FPL | I1674: =MAX(original!I1674,piwebapi_edit!I1674,car_edit!I1674) -> 0 | J1674: =MAX(original!J1674,piwebapi_edit!J1674,car_edit!J1674) -> 0

Sheet parts -->

Sheet original
A1: Asset ID | B1: Location Address | C1: JEA GIS Object ID | D1: Sewer Maintenance District | E1: County | F1: Best Estimate of Install Date of Station | G1: Year of Install | H1: Electrical Supplier | I1: JEA Actual ADF (GPD) | J1: JEA Design PHF (GPM) | K1: PS Class
A2: BPS-000639 | B2: 2740 CR 210 | C2: 205269 | D2: St Johns Grid | E2: St Johns | F2: 42676 | G2: =F2 -> 42676 | H2: JEA | I2: =IF(ISNA(VLOOKUP(A2,'[1]Craig Eval'!A:C,3,FALSE)),"",(VLOOKUP(A2,'[1]Craig Eval'!A:C,3,FALSE))*1000) | J2: =IF(ISNA(VLOOKUP(A2,'[1]Craig Eval'!A:M,13,FALSE)),"",VLOOKUP(A2,'[1]Craig Eval'!A:M,13,FALSE)) | K2: 4
A3: BPS-001645 | B3: 4193 OLDFIELD CROSSING | C3: 1729 | D3: South Grid | E3: Duval | F3: 42755 | G3: =F3 -> 42755 | H3: JEA | I3: =IF(ISNA(VLOOKUP(A3,'[1]Craig Eval'!A:C,3,FALSE)),"",(VLOOKUP(A3,'[1]Craig Eval'!A:C,3,FALSE))*1000) | J3: =IF(ISNA(VLOOKUP(A3,'[1]Craig Eval'!A:M,13,FALSE)),"",VLOOKUP(A3,'[1]Craig Eval'!A:M,13,FALSE)) | K3: 4
A4: BPS-001950 | B4: 4241 SAN CLERC | C4: 16966 | D4: South Grid | E4: Duval | F4: 41143 | G4: =F4 -> 41143 | H4: JEA | I4: =IF(ISNA(VLOOKUP(A4,'[1]Craig Eval'!A:C,3,FALSE)),"",(VLOOKUP(A4,'[1]Craig Eval'!A:C,3,FALSE))*1000) -> 24143.567 | J4: =IF(ISNA(VLOOKUP(A4,'[1]Craig Eval'!A:M,13,FALSE)),"",VLOOKUP(A4,'[1]Craig Eval'!A:M,13,FALSE)) -> 69.028726 | K4: 4
A5: BPS-002867 | B5: 8617 WESTERN WAY | C5: 204646 | D5: South Grid | E5: Duval | F5: 38533 | G5: =F5 -> 38533 | H5: JEA | I5: =IF(ISNA(VLOOKUP(A5,'[1]Craig Eval'!A:C,3,FALSE)),"",(VLOOKUP(A5,'[1]Craig Eval'!A:C,3,FALSE))*1000) | J5: =IF(ISNA(VLOOKUP(A5,'[1]Craig Eval'!A:M,13,FALSE)),"",VLOOKUP(A5,'[1]Craig Eval'!A:M,13,FALSE)) | K5: 4
A6: BPS-003387 | B6: 106 TWIN CREEKS Dr | C6: 55153 | D6: St Johns Grid | E6: Duval | F6: 39420 | G6: =F6 -> 39420 | H6: JEA | I6: =IF(ISNA(VLOOKUP(A6,'[1]Craig Eval'!A:C,3,FALSE)),"",(VLOOKUP(A6,'[1]Craig Eval'!A:C,3,FALSE))*1000) | J6: =IF(ISNA(VLOOKUP(A6,'[1]Craig Eval'!A:M,13,FALSE)),"",VLOOKUP(A6,'[1]Craig Eval'!A:M,13,FALSE)) | K6: 4
A7: BPS-004153 | B7: 6850 Energy Center Drive | C7: 256468 | D7: South Grid | E7: Duval | F7: 43635 | G7: =F7 -> 43635 | H7: JEA | I7: =IF(ISNA(VLOOKUP(A7,'[1]Craig Eval'!A:C,3,FALSE)),"",(VLOOKUP(A7,'[1]Craig Eval'!A:C,3,FALSE))*1000) | J7: =IF(ISNA(VLOOKUP(A7,'[1]Craig Eval'!A:M,13,FALSE)),"",VLOOKUP(A7,'[1]Craig Eval'!A:M,13,FALSE)) | K7: 4
A8: BPS-004187 | B8: 7806 RAMPART RD | C8: 277052 | D8: West Grid | E8: Duval | F8: 44197 | G8: =F8 -> 44197 | H8: JEA | I8: =IF(ISNA(VLOOKUP(A8,'[1]Craig Eval'!A:C,3,FALSE)),"",(VLOOKUP(A8,'[1]Craig Eval'!A:C,3,FALSE))*1000) | J8: =IF(ISNA(VLOOKUP(A8,'[1]Craig Eval'!A:M,13,FALSE)),"",VLOOKUP(A8,'[1]Craig Eval'!A:M,13,FALSE)) | K8: 4
A9: BPS-004228 | B9: 10477 BRADLEY RD BOOSTER | C9: 1329 | D9: East Grid | E9: Duval | F9: 44319 | G9: =F9 -> 44319 | H9: JEA | K9: 4
A10: BPS-004296 | B10: 3742 ROBENA ROAD | C10: 315233 | D10: North Grid | E10: Duval | F10: 45078 | G10: =F10 -> 45078 | H10: JEA | K10: 4
A11: BPS-004333 | B11: 85008 ART WILSON LN | C11: 354434 | D11: Nassau Grid | E11: Nassau | F11: 45350 | G11: =F11 -> 45350 | H11: FPL | K11: 4
A12: LS-000001 | B12: 12770 1ST ST | C12: 1907 | D12: North Grid | E12: Duval | F12: 25569 | G12: =F12 -> 25569 | H12: JEA | I12: =IF(ISNA(VLOOKUP(A12,'[1]Craig Eval'!A:C,3,FALSE)),"",(VLOOKUP(A12,'[1]Craig Eval'!A:C,3,FALSE))*1000) | J12: =IF(ISNA(VLOOKUP(A12,'[1]Craig Eval'!A:M,13,FALSE)),"",VLOOKUP(A12,'[1]Craig Eval'!A:M,13,FALSE)) | K12: 1
A13: LS-000002 | B13: 2580 1ST ST W | C13: 54481 | D13: North Grid | E13: Duval | F13: 18264 | G13: =F13 -> 18264 | H13: JEA | I13: =IF(ISNA(VLOOKUP(A13,'[1]Craig Eval'!A:C,3,FALSE)),"",(VLOOKUP(A13,'[1]Craig Eval'!A:C,3,FALSE))*1000) -> 772.33629 | J13: =IF(ISNA(VLOOKUP(A13,'[1]Craig Eval'!A:M,13,FALSE)),"",VLOOKUP(A13,'[1]Craig Eval'!A:M,13,FALSE)) -> 2.3731941 | K13: 1
A14: LS-000004 | B14: 1999 30TH ST W | C14: 1983 | D14: North Grid | E14: Duval | F14: 35431 | G14: =F14 -> 35431 | H14: JEA | I14: =IF(ISNA(VLOOKUP(A14,'[1]Craig Eval'!A:C,3,FALSE)),"",(VLOOKUP(A14,'[1]Craig Eval'!A:C,3,FALSE))*1000) -> 16897.508 | J14: =IF(ISNA(VLOOKUP(A14,'[1]Craig Eval'!A:M,13,FALSE)),"",VLOOKUP(A14,'[1]Craig Eval'!A:M,13,FALSE)) -> 48.977382 | K14: 1
A15: LS-000005 | B15: 94 32ND ST E | C15: 1298 | D15: North Grid | E15: Duval | F15: 34700 | G15: =F15 -> 34700 | H15: JEA | I15: =IF(ISNA(VLOOKUP(A15,'[1]Craig Eval'!A:C,3,FALSE)),"",(VLOOKUP(A15,'[1]Craig Eval'!A:C,3,FALSE))*1000) -> 131570.51 | J15: =IF(ISNA(VLOOKUP(A15,'[1]Craig Eval'!A:M,13,FALSE)),"",VLOOKUP(A15,'[1]Craig Eval'!A:M,13,FALSE)) -> 339.89131 | K15: 4
A16: LS-000006 | B16: 1870 41ST ST W | C16: 1804 | D16: North Grid | E16: Duval | F16: 32143 | G16: =F16 -> 32143 | H16: JEA | I16: =IF(ISNA(VLOOKUP(A16,'[1]Craig Eval'!A:C,3,FALSE)),"",(VLOOKUP(A16,'[1]Craig Eval'!A:C,3,FALSE))*1000) -> 47950.201 | J16: =IF(ISNA(VLOOKUP(A16,'[1]Craig Eval'!A:M,13,FALSE)),"",VLOOKUP(A16,'[1]Craig Eval'!A:M,13,FALSE)) -> 132.64588 | K16: 3
A17: LS-000007 | B17: 1646 45TH ST W | C17: 54482 | D17: North Grid | E17: Duval | F17: 21916 | G17: =F17 -> 21916 | H17: JEA | I17: =IF(ISNA(VLOOKUP(A17,'[1]Craig Eval'!A:C,3,FALSE)),"",(VLOOKUP(A17,'[1]Craig Eval'!A:C,3,FALSE))*1000) -> 25946.152 | J17: =IF(ISNA(VLOOKUP(A17,'[1]Craig Eval'!A:M,13,FALSE)),"",VLOOKUP(A17,'[1]Craig Eval'!A:M,13,FALSE)) -> 73.958138 | K17: 2
A18: LS-000013 | B18: 2809 5TH ST W | C18: 1941 | D18: North Grid | E18: Duval | F18: 21186 | G18: =F18 -> 21186 | H18: JEA | I18: =IF(ISNA(VLOOKUP(A18,'[1]Craig Eval'!A:C,3,FALSE)),"",(VLOOKUP(A18,'[1]Craig Eval'!A:C,3,FALSE))*1000) | J18: =IF(ISNA(VLOOKUP(A18,'[1]Craig Eval'!A:M,13,FALSE)),"",VLOOKUP(A18,'[1]Craig Eval'!A:M,13,FALSE)) | K18: 4
A19: LS-000014 | B19: 5233 5TH ST W | C19: 1940 | D19: West Grid | E19: Duval | F19: 19725 | G19: =F19 -> 19725 | H19: JEA | I19: =IF(ISNA(VLOOKUP(A19,'[1]Craig Eval'!A:C,3,FALSE)),"",(VLOOKUP(A19,'[1]Craig Eval'!A:C,3,FALSE))*1000) | J19: =IF(ISNA(VLOOKUP(A19,'[1]Craig Eval'!A:M,13,FALSE)),"",VLOOKUP(A19,'[1]Craig Eval'!A:M,13,FALSE)) | K19: 4
A20: LS-000017 | B20: 239 68TH ST W | C20: 1534 | D20: North Grid | E20: Duval | F20: 29221 | G20: =F20 -> 29221 | H20: JEA | I20: =IF(ISNA(VLOOKUP(A20,'[1]Craig Eval'!A:C,3,FALSE)),"",(VLOOKUP(A20,'[1]Craig Eval'!A:C,3,FALSE))*1000) -> 6053.0151 | J20: =IF(ISNA(VLOOKUP(A20,'[1]Craig Eval'!A:M,13,FALSE)),"",VLOOKUP(A20,'[1]Craig Eval'!A:M,13,FALSE)) -> 18.0632 | K20: 1
A21: LS-000018 | B21: 7200 AC SKINNER PY | C21: 1710 | D21: South Grid | E21: Duval | F21: 30317 | G21: =F21 -> 30317 | H21: JEA | I21: =IF(ISNA(VLOOKUP(A21,'[1]Craig Eval'!A:C,3,FALSE)),"",(VLOOKUP(A21,'[1]Craig Eval'!A:C,3,FALSE))*1000) -> 243665.13 | J21: =IF(ISNA(VLOOKUP(A21,'[1]Craig Eval'!A:M,13,FALSE)),"",VLOOKUP(A21,'[1]Craig Eval'!A:M,13,FALSE)) -> 595.21011 | K21: 4
A22: LS-000019 | B22: 5640 101ST ST | C22: 1252 | D22: West Grid | E22: Duval | F22: 18264 | G22: =F22 -> 18264 | H22: JEA | I22: =IF(ISNA(VLOOKUP(A22,'[1]Craig Eval'!A:C,3,FALSE)),"",(VLOOKUP(A22,'[1]Craig Eval'!A:C,3,FALSE))*1000) -> 16416.713 | J22: =IF(ISNA(VLOOKUP(A22,'[1]Craig Eval'!A:M,13,FALSE)),"",VLOOKUP(A22,'[1]Craig Eval'!A:M,13,FALSE)) -> 47.63218 | K22: 1
A23: LS-000023 | B23: MAGNOLIA VALLEY DR. 5097 | C23: 85617 | D23: West Grid | E23: Duval | F23: 40162 | G23: =F23 -> 40162 | H23: JEA | I23: =IF(ISNA(VLOOKUP(A23,'[1]Craig Eval'!A:C,3,FALSE)),"",(VLOOKUP(A23,'[1]Craig Eval'!A:C,3,FALSE))*1000) -> 5303.4806 | J23: =IF(ISNA(VLOOKUP(A23,'[1]Craig Eval'!A:M,13,FALSE)),"",VLOOKUP(A23,'[1]Craig Eval'!A:M,13,FALSE)) -> 15.871636 | K23: 1
... A27: LS-000039 | B27: 9902 103RD ST | C27: 1655 | D27: West Grid | E27: Duval | F27: 34335 | G27: =F27 -> 34335 | H27: JEA | I27: =IF(ISNA(VLOOKUP(A27,'[1]Craig Eval'!A:C,3,FALSE)),"",(VLOOKUP(A27,'[1]Craig Eval'!A:C,3,FALSE))*1000) -> 63218.744 | J27: =IF(ISNA(VLOOKUP(A27,'[1]Craig Eval'!A:M,13,FALSE)),"",VLOOKUP(A27,'[1]Craig Eval'!A:M,13,FALSE)) -> 172.07992 | K27: 2
A28: LS-000045 | B28: 5104 118TH ST | C28: 1256 | D28: West Grid | E28: Duval | F28: 26299 | G28: =F28 -> 26299 | H28: JEA | I28: 10595000 | J28: 11100 | K28: 4
A29: LS-000047 | B29: 5823 118TH ST | C29: 12161 | D29: West Grid | E29: Duval | F29: 37846 | G29: =F29 -> 37846 | H29: JEA | I29: =IF(ISNA(VLOOKUP(A29,'[1]Craig Eval'!A:C,3,FALSE)),"",(VLOOKUP(A29,'[1]Craig Eval'!A:C,3,FALSE))*1000) -> 39761.23 | J29: =IF(ISNA(VLOOKUP(A29,'[1]Craig Eval'!A:M,13,FALSE)),"",VLOOKUP(A29,'[1]Craig Eval'!A:M,13,FALSE)) -> 111.09368 | K29: 1
A30: LS-000048 | B30: 8350 118TH ST | C30: 1562 | D30: West Grid | E30: Duval | F30: 36441 | G30: =F30 -> 36441 | H30: JEA | I30: =IF(ISNA(VLOOKUP(A30,'[1]Craig Eval'!A:C,3,FALSE)),"",(VLOOKUP(A30,'[1]Craig Eval'!A:C,3,FALSE))*1000) -> 42912.255 | J30: =IF(ISNA(VLOOKUP(A30,'[1]Craig Eval'!A:M,13,FALSE)),"",VLOOKUP(A30,'[1]Craig Eval'!A:M,13,FALSE)) -> 119.42333 | K30: 1
A31: LS-000057 | B31: 3215 ABBEYFIELD LN | C31: 1139 | D31: East Grid | E31: Duval | F31: 29221 | G31: =F31 -> 29221 | H31: JEA | I31: =IF(ISNA(VLOOKUP(A31,'[1]Craig Eval'!A:C,3,FALSE)),"",(VLOOKUP(A31,'[1]Craig Eval'!A:C,3,FALSE))*1000) -> 147421.87 | J31: =IF(ISNA(VLOOKUP(A31,'[1]Craig Eval'!A:M,13,FALSE)),"",VLOOKUP(A31,'[1]Craig Eval'!A:M,13,FALSE)) -> 377.25553 | K31: 1
A32: LS-000058 | B32: 5180 ABEL LN | C32: 1490 | D32: West Grid | E32: Duval | F32: 26753 | G32: =F32 -> 26753 | H32: JEA | I32: =IF(ISNA(VLOOKUP(A32,'[1]Craig Eval'!A:C,3,FALSE)),"",(VLOOKUP(A32,'[1]Craig Eval'!A:C,3,FALSE))*1000) -> 17986.645 | J32: =IF(ISNA(VLOOKUP(A32,'[1]Craig Eval'!A:M,13,FALSE)),"",VLOOKUP(A32,'[1]Craig Eval'!A:M,13,FALSE)) -> 52.017385 | K32: 1
A33: LS-000060 | B33: 12733 ABESS BV | C33: 1826 | D33: East Grid | E33: Duval | F33: 31778 | G33: =F33 -> 31778 | H33: JEA | I33: =IF(ISNA(VLOOKUP(A33,'[1]Craig Eval'!A:C,3,FALSE)),"",(VLOOKUP(A33,'[1]Craig Eval'!A:C,3,FALSE))*1000) -> 355410.04 | J33: =IF(ISNA(VLOOKUP(A33,'[1]Craig Eval'!A:M,13,FALSE)),"",VLOOKUP(A33,'[1]Craig Eval'!A:M,13,FALSE)) -> 833.93896 | K33: 4
A34: LS-000063 | B34: 8752 ACANTHUS DR | C34: 1564 | D34: West Grid | E34: Duval | F34: 25569 | G34: =F34 -> 25569 | H34: JEA | I34: =IF(ISNA(VLOOKUP(A34,'[1]Craig Eval'!A:C,3,FALSE)),"",(VLOOKUP(A34,'[1]Craig Eval'!A:C,3,FALSE))*1000) -> 196719.25 | J34: =IF(ISNA(VLOOKUP(A34,'[1]Craig Eval'!A:M,13,FALSE)),"",VLOOKUP(A34,'[1]Craig Eval'!A:M,13,FALSE)) -> 490.61794 | K34: 3
A35: LS-000067 | B35: 11933 ACOSTA RD | C35: 1968 | D35: South Grid | E35: Duval | F35: 29221 | G35: =F35 -> 29221 | H35: JEA | I35: =IF(ISNA(VLOOKUP(A35,'[1]Craig Eval'!A:C,3,FALSE)),"",(VLOOKUP(A35,'[1]Craig Eval'!A:C,3,FALSE))*1000) | J35: =IF(ISNA(VLOOKUP(A35,'[1]Craig Eval'!A:M,13,FALSE)),"",VLOOKUP(A35,'[1]Craig Eval'!A:M,13,FALSE)) | K35: 1
A36: LS-000069 | B36: 505 ADDOR LN | C36: 1369 | D36: West Grid | E36: Duval | F36: 33813 | G36: =F36 -> 33813 | H36: JEA | I36: =IF(ISNA(VLOOKUP(A36,'[1]Craig Eval'!A:C,3,FALSE)),"",(VLOOKUP(A36,'[1]Craig Eval'!A:C,3,FALSE))*1000) -> 1532.786 | J36: =IF(ISNA(VLOOKUP(A36,'[1]Craig Eval'!A:M,13,FALSE)),"",VLOOKUP(A36,'[1]Craig Eval'!A:M,13,FALSE)) -> 4.6781078 | K36: 1
A37: LS-000070 | B37: 9374 ADELAID DR | C37: 2241 | D37: West Grid | E37: Duval | F37: 37117 | G37: =F37 -> 37117 | H37: JEA | I37: =IF(ISNA(VLOOKUP(A37,'[1]Craig Eval'!A:C,3,FALSE)),"",(VLOOKUP(A37,'[1]Craig Eval'!A:C,3,FALSE))*1000) -> 91415.151 | J37: =IF(ISNA(VLOOKUP(A37,'[1]Craig Eval'!A:M,13,FALSE)),"",VLOOKUP(A37,'[1]Craig Eval'!A:M,13,FALSE)) -> 242.80845 | K37: 2
A38: LS-000071 | B38: 2844 ADELE RD | C38: 2012 | D38: South Grid | E38: Duval | F38: 29221 | G38: =F38 -> 29221 | H38: JEA | I38: =IF(ISNA(VLOOKUP(A38,'[1]Craig Eval'!A:C,3,FALSE)),"",(VLOOKUP(A38,'[1]Craig Eval'!A:C,3,FALSE))*1000) -> 8177.49 | J38: =IF(ISNA(VLOOKUP(A38,'[1]Craig Eval'!A:M,13,FALSE)),"",VLOOKUP(A38,'[1]Craig Eval'!A:M,13,FALSE)) -> 24.228523 | K38: 1
A39: LS-000073 | B39: 13650 AEROSPACE WAY | C39: 89458 | D39: West Grid | E39: Duval | F39: 31048 | G39: =F39 -> 31048 | H39: JEA | I39: =IF(ISNA(VLOOKUP(A39,'[1]Craig Eval'!A:C,3,FALSE)),"",(VLOOKUP(A39,'[1]Craig Eval'!A:C,3,FALSE))*1000) -> 6798.2711 | J39: =IF(ISNA(VLOOKUP(A39,'[1]Craig Eval'!A:M,13,FALSE)),"",VLOOKUP(A39,'[1]Craig Eval'!A:M,13,FALSE)) -> 20.23344 | K39: 1
A40: LS-000074 | B40: 125 AFTON LN | C40: 1963 | D40: St Johns Grid | E40: Duval | F40: 36039 | G40: =F40 -> 36039 | H40: JEA | I40: =IF(ISNA(VLOOKUP(A40,'[1]Craig Eval'!A:C,3,FALSE)),"",(VLOOKUP(A40,'[1]Craig Eval'!A:C,3,FALSE))*1000) | J40: =IF(ISNA(VLOOKUP(A40,'[1]Craig Eval'!A:M,13,FALSE)),"",VLOOKUP(A40,'[1]Craig Eval'!A:M,13,FALSE)) | K40: 1
... A504: LS-001092 | B504: 7551 HOGAN RD | C504: 1270 | D504: South Grid | E504: Duval | F504: 25569 | G504: =F504 -> 25569 | H504: JEA | I504: =IF(ISNA(VLOOKUP(A504,'[1]Craig Eval'!A:C,3,FALSE)),"",(VLOOKUP(A504,'[1]Craig Eval'!A:C,3,FALSE))*1000) -> 34765.553 | J504: =IF(ISNA(VLOOKUP(A504,'[1]Craig Eval'!A:M,13,FALSE)),"",VLOOKUP(A504,'[1]Craig Eval'!A:M,13,FALSE)) -> 97.786793 | K504: 1
A505: LS-001093 | B505: 7834 HOLIDAY RD S | C505: 1395 | D505: East Grid | E505: Duval | F505: 29830 | G505: =F505 -> 29830 | H505: JEA | I505: 1183000 | J505: 2400 | K505: 4
A506: LS-001094 | B506: 3655 HOLLY GROVE AV | C506: 17291 | D506: South Grid | E506: Duval | F506: 33161 | G506: =F506 -> 33161 | H506: JEA | I506: =IF(ISNA(VLOOKUP(A506,'[1]Craig Eval'!A:C,3,FALSE)),"",(VLOOKUP(A506,'[1]Craig Eval'!A:C,3,FALSE))*1000) -> 6783.1955 | J506: =IF(ISNA(VLOOKUP(A506,'[1]Craig Eval'!A:M,13,FALSE)),"",VLOOKUP(A506,'[1]Craig Eval'!A:M,13,FALSE)) -> 20.189622 | K506: 1
...

Sheet piwebapi_edit
A1: Asset ID | B1: Location Address | C1: JEA GIS Object ID | D1: Sewer Maintenance District | E1: County | F1: Best Estimate of Install Date of Station | G1: Year of Install | H1: Electrical Supplier | I1: JEA Actual ADF (GPD) | J1: JEA Design PHF (GPM) | K1: PS Class
A2: BPS-000639 | B2: 2740 CR 210 | C2: 205269 | D2: St Johns Grid | E2: St Johns | F2: 42676 | G2: =F2 -> 42676 | H2: JEA | K2: 4
A3: BPS-001645 | B3: 4193 OLDFIELD CROSSING | C3: 1729 | D3: South Grid | E3: Duval | F3: 42755 | G3: =F3 -> 42755 | H3: JEA | K3: 4
A4: BPS-001950 | B4: 4241 SAN CLERC | C4: 16966 | D4: South Grid | E4: Duval | F4: 41143 | G4: =F4 -> 41143 | H4: JEA | K4: 4
A5: BPS-002867 | B5: 8617 WESTERN WAY | C5: 204646 | D5: South Grid | E5: Duval | F5: 38533 | G5: =F5 -> 38533 | H5: JEA | K5: 4
A6: BPS-003387 | B6: 106 TWIN CREEKS Dr | C6: 55153 | D6: St Johns Grid | E6: Duval | F6: 39420 | G6: =F6 -> 39420 | H6: JEA | K6: 4
A7: BPS-004153 | B7: 6850 Energy Center Drive | C7: 256468 | D7: South Grid | E7: Duval | F7: 43635 | G7: =F7 -> 43635 | H7: JEA | K7: 4
A8: BPS-004187 | B8: 7806 RAMPART RD | C8: 277052 | D8: West Grid | E8: Duval | F8: 44197 | G8: =F8 -> 44197 | H8: JEA | K8: 4
A9: BPS-004228 | B9: 10477 BRADLEY RD BOOSTER | C9: 1329 | D9: East Grid | E9: Duval | F9: 44319 | G9: =F9 -> 44319 | H9: JEA | K9: 4
A10: BPS-004296 | B10: 3742 ROBENA ROAD | C10: 315233 | D10: North Grid | E10: Duval | F10: 45078 | G10: =F10 -> 45078 | H10: JEA | K10: 4
A11: BPS-004333 | B11: 85008 ART WILSON LN | C11: 354434 | D11: Nassau Grid | E11: Nassau | F11: 45350 | G11: =F11 -> 45350 | H11: FPL | K11: 4
A12: LS-000001 | B12: 12770 1ST ST | C12: 1907 | D12: North Grid | E12: Duval | F12: 25569 | G12: =F12 -> 25569 | H12: JEA | I12: 3800.0027 | J12: 391.9503 | K12: 1
A13: LS-000002 | B13: 2580 1ST ST W | C13: 54481 | D13: North Grid | E13: Duval | F13: 18264 | G13: =F13 -> 18264 | H13: JEA | I13: 679.30483 | J13: 178.69535 | K13: 1
A14: LS-000004 | B14: 1999 30TH ST W | C14: 1983 | D14: North Grid | E14: Duval | F14: 35431 | G14: =F14 -> 35431 | H14: JEA | I14: 8305.0375 | J14: 139.41558 | K14: 1
A15: LS-000005 | B15: 94 32ND ST E | C15: 1298 | D15: North Grid | E15: Duval | F15: 34700 | G15: =F15 -> 34700 | H15: JEA | I15: 158687.74 | J15: 707.47431 | K15: 4
A16: LS-000006 | B16: 1870 41ST ST W | C16: 1804 | D16: North Grid | E16: Duval | F16: 32143 | G16: =F16 -> 32143 | H16: JEA | I16: 111175.11 | J16: 1009.4588 | K16: 3
A17: LS-000007 | B17: 1646 45TH ST W | C17: 54482 | D17: North Grid | E17: Duval | F17: 21916 | G17: =F17 -> 21916 | H17: JEA | I17: 37275.195 | J17: 416.13725 | K17: 2
A18: LS-000013 | B18: 2809 5TH ST W | C18: 1941 | D18: North Grid | E18: Duval | F18: 21186 | G18: =F18 -> 21186 | H18: JEA | K18: 4
A19: LS-000014 | B19: 5233 5TH ST W | C19: 1940 | D19: West Grid | E19: Duval | F19: 19725 | G19: =F19 -> 19725 | H19: JEA | K19: 4
A20: LS-000017 | B20: 239 68TH ST W | C20: 1534 | D20: North Grid | E20: Duval | F20: 29221 | G20: =F20 -> 29221 | H20: JEA | I20: 4148.0654 | J20: 161.84871 | K20: 1
A21: LS-000018 | B21: 7200 AC SKINNER PY | C21: 1710 | D21: South Grid | E21: Duval | F21: 30317 | G21: =F21 -> 30317 | H21: JEA | K21: 4
A22: LS-000019 | B22: 5640 101ST ST | C22: 1252 | D22: West Grid | E22: Duval | F22: 18264 | G22: =F22 -> 18264 | H22: JEA | I22: 24964.525 | J22: 87.938139 | K22: 1
A23: LS-000023 | B23: MAGNOLIA VALLEY DR. 5097 | C23: 85617 | D23: West Grid | E23: Duval | F23: 40162 | G23: =F23 -> 40162 | H23: JEA | I23: 8526.1175 | J23: 334.90585 | K23: 1
A24: LS-000026 | B24: 6650 103RD ST | C24: 26881 | D24: West Grid | E24: Duval | F24: 32927 | G24: =F24 -> 32927 | H24: JEA | I24: 5872.579 | J24: 164.91228 | K24: 1
A25: LS-000033 | B25: 7960 103RD ST | C25: 1286 | D25: West Grid | E25: Duval | F25: 31778 | G25: =F25 -> 31778 | H25: JEA | I25: 13355.874 | J25: 116.98851 | K25: 1
A26: LS-000034 | B26: 9380 103RD ST | C26: 1656 | D26: West Grid | E26: Duval | F26: 36892 | G26: =F26 -> 36892 | H26: JEA | I26: 9962.3103 | J26: 58.357324 | K26: 1
A27: LS-000039 | B27: 9902 103RD ST | C27: 1655 | D27: West Grid | E27: Duval | F27: 34335 | G27: =F27 -> 34335 | H27: JEA | I27: 78098.778 | J27: 795.65975 | K27: 2
A28: LS-000045 | B28: 5104 118TH ST | C28: 1256 | D28: West Grid | E28: Duval | F28: 26299 | G28: =F28 -> 26299 | H28: JEA | K28: 4
A29: LS-000047 | B29: 5823 118TH ST | C29: 12161 | D29: West Grid | E29: Duval | F29: 37846 | G29: =F29 -> 37846 | H29: JEA | I29: 156740.52 | J29: 401.40041 | K29: 1
A30: LS-000048 | B30: 8350 118TH ST | C30: 1562 | D30: West Grid | E30: Duval | F30: 36441 | G30: =F30 -> 36441 | H30: JEA | I30: 43395.552 | J30: 250.71292 | K30: 1
A31: LS-000057 | B31: 3215 ABBEYFIELD LN | C31: 1139 | D31: East Grid | E31: Duval | F31: 29221 | G31: =F31 -> 29221 | H31: JEA | I31: 77771.083 | J31: 431.74386 | K31: 1
A32: LS-000058 | B32: 5180 ABEL LN | C32: 1490 | D32: West Grid | E32: Duval | F32: 26753 | G32: =F32 -> 26753 | H32: JEA | I32: 19641.488 | J32: 322.96819 | K32: 1
A33: LS-000060 | B33: 12733 ABESS BV | C33: 1826 | D33: East Grid | E33: Duval | F33: 31778 | G33: =F33 -> 31778 | H33: JEA | K33: 4
A34: LS-000063 | B34: 8752 ACANTHUS DR | C34: 1564 | D34: West Grid | E34: Duval | F34: 25569 | G34: =F34 -> 25569 | H34: JEA | I34: 225935.57 | J34: 445.32817 | K34: 3
A35: LS-000067 | B35: 11933 ACOSTA RD | C35: 1968 | D35: South Grid | E35: Duval | F35: 29221 | G35: =F35 -> 29221 | H35: JEA | I35: 10740.192 | J35: 359.74633 | K35: 1
A36: LS-000069 | B36: 505 ADDOR LN | C36: 1369 | D36: West Grid | E36: Duval | F36: 33813 | G36: =F36 -> 33813 | H36: JEA | I36: 1503.892 | J36: 218.86513 | K36: 1
A37: LS-000070 | B37: 9374 ADELAID DR | C37: 2241 | D37: West Grid | E37: Duval | F37: 37117 | G37: =F37 -> 37117 | H37: JEA | I37: 103743.19 | J37: 398.70769 | K37: 2
A38: LS-000071 | B38: 2844 ADELE RD | C38: 2012 | D38: South Grid | E38: Duval | F38: 29221 | G38: =F38 -> 29221 | H38: JEA | I38: 11032.907 | J38: 33.82726 | K38: 1
A39: LS-000073 | B39: 13650 AEROSPACE WAY | C39: 89458 | D39: West Grid | E39: Duval | F39: 31048 | G39: =F39 -> 31048 | H39: JEA | I39: 595.60672 | J39: 74.420632 | K39: 1
A40: LS-000074 | B40: 125 AFTON LN | C40: 1963 | D40: St Johns Grid | E40: Duval | F40: 36039 | G40: =F40 -> 36039 | H40: JEA | I40: 32722.459 | J40: 163.58411 | K40: 1
...

Sheet car_edit
A1: Asset ID | B1: Location Address | C1: JEA GIS Object ID | D1: Sewer Maintenance District | E1: County | F1: Best Estimate of Install Date of Station | G1: Year of Install | H1: Electrical Supplier | I1: JEA Actual ADF (GPD) | J1: JEA Design PHF (GPM) | K1: PS Class
A2: BPS-000639 | B2: 2740 CR 210 | C2: 205269 | D2: St Johns Grid | E2: St Johns | F2: 42676 | G2: =F2 -> 42676 | H2: JEA | I2: 2861084.5 | J2: 7000
A3: BPS-001645 | B3: 4193 OLDFIELD CROSSING | C3: 1729 | D3: South Grid | E3: Duval | F3: 42755 | G3: =F3 -> 42755 | H3: JEA | I3: 2714538.5 | J3: 9370
A4: BPS-001950 | B4: 4241 SAN CLERC | C4: 16966 | D4: South Grid | E4: Duval | F4: 41143 | G4: =F4 -> 41143 | H4: JEA | I4: 932000 | J4: 3040
A5: BPS-002867 | B5: 8617 WESTERN WAY | C5: 204646 | D5: South Grid | E5: Duval | F5: 38533 | G5: =F5 -> 38533 | H5: JEA | I5: 2827540.5 | J5: 5000
A6: BPS-003387 | B6: 106 TWIN CREEKS Dr | C6: 55153 | D6: St Johns Grid | E6: Duval | F6: 39420 | G6: =F6 -> 39420 | H6: JEA | I6: 2481327.6 | J6: 4400
A7: BPS-004153 | B7: 6850 Energy Center Drive | C7: 256468 | D7: South Grid | E7: Duval | F7: 43635 | G7: =F7 -> 43635 | H7: JEA | I7: 166464 | J7: 1200
A8: BPS-004187 | B8: 7806 RAMPART RD | C8: 277052 | D8: West Grid | E8: Duval | F8: 44197 | G8: =F8 -> 44197 | H8: JEA | I8: 2297937.6 | J8: 5000
A9: BPS-004228 | B9: 10477 BRADLEY RD BOOSTER | C9: 1329 | D9: East Grid | E9: Duval | F9: 44319 | G9: =F9 -> 44319 | H9: JEA | I9: 12497059 | J9: 19500
A10: BPS-004296 | B10: 3742 ROBENA ROAD | C10: 315233 | D10: North Grid | E10: Duval | F10: 45078 | G10: =F10 -> 45078 | H10: JEA
A11: BPS-004333 | B11: 85008 ART WILSON LN | C11: 354434 | D11: Nassau Grid | E11: Nassau | F11: 45350 | G11: =F11 -> 45350 | H11: FPL
A12: LS-000001 | B12: 12770 1ST ST | C12: 1907 | D12: North Grid | E12: Duval | F12: 25569 | G12: =F12 -> 25569 | H12: JEA
A13: LS-000002 | B13: 2580 1ST ST W | C13: 54481 | D13: North Grid | E13: Duval | F13: 18264 | G13: =F13 -> 18264 | H13: JEA
A14: LS-000004 | B14: 1999 30TH ST W | C14: 1983 | D14: North Grid | E14: Duval | F14: 35431 | G14: =F14 -> 35431 | H14: JEA
A15: LS-000005 | B15: 94 32ND ST E | C15: 1298 | D15: North Grid | E15: Duval | F15: 34700 | G15: =F15 -> 34700 | H15: JEA | I15: 1014995.5 | J15: 2500
A16: LS-000006 | B16: 1870 41ST ST W | C16: 1804 | D16: North Grid | E16: Duval | F16: 32143 | G16: =F16 -> 32143 | H16: JEA | I16: 94847.049 | J16: 1500
A17: LS-000007 | B17: 1646 45TH ST W | C17: 54482 | D17: North Grid | E17: Duval | F17: 21916 | G17: =F17 -> 21916 | H17: JEA
A18: LS-000013 | B18: 2809 5TH ST W | C18: 1941 | D18: North Grid | E18: Duval | F18: 21186 | G18: =F18 -> 21186 | H18: JEA | I18: 1852554.1 | J18: 10000
A19: LS-000014 | B19: 5233 5TH ST W | C19: 1940 | D19: West Grid | E19: Duval | F19: 19725 | G19: =F19 -> 19725 | H19: JEA | I19: 510479.35 | J19: 1250
A20: LS-000017 | B20: 239 68TH ST W | C20: 1534 | D20: North Grid | E20: Duval | F20: 29221 | G20: =F20 -> 29221 | H20: JEA
A21: LS-000018 | B21: 7200 AC SKINNER PY | C21: 1710 | D21: South Grid | E21: Duval | F21: 30317 | G21: =F21 -> 30317 | H21: JEA | I21: 1224444.4 | J21: 3770
A22: LS-000019 | B22: 5640 101ST ST | C22: 1252 | D22: West Grid | E22: Duval | F22: 18264 | G22: =F22 -> 18264 | H22: JEA
A23: LS-000023 | B23: MAGNOLIA VALLEY DR. 5097 | C23: 85617 | D23: West Grid | E23: Duval | F23: 40162 | G23: =F23 -> 40162 | H23: JEA
A24: LS-000026 | B24: 6650 103RD ST | C24: 26881 | D24: West Grid | E24: Duval | F24: 32927 | G24: =F24 -> 32927 | H24: JEA
A25: LS-000033 | B25: 7960 103RD ST | C25: 1286 | D25: West Grid | E25: Duval | F25: 31778 | G25: =F25 -> 31778 | H25: JEA
A26: LS-000034 | B26: 9380 103RD ST | C26: 1656 | D26: West Grid | E26: Duval | F26: 36892 | G26: =F26 -> 36892 | H26: JEA
A27: LS-000039 | B27: 9902 103RD ST | C27: 1655 | D27: West Grid | E27: Duval | F27: 34335 | G27: =F27 -> 34335 | H27: JEA
A28: LS-000045 | B28: 5104 118TH ST | C28: 1256 | D28: West Grid | E28: Duval | F28: 26299 | G28: =F28 -> 26299 | H28: JEA | I28: 3940176 | J28: 15000
A29: LS-000047 | B29: 5823 118TH ST | C29: 12161 | D29: West Grid | E29: Duval | F29: 37846 | G29: =F29 -> 37846 | H29: JEA
A30: LS-000048 | B30: 8350 118TH ST | C30: 1562 | D30: West Grid | E30: Duval | F30: 36441 | G30: =F30 -> 36441 | H30: JEA
A31: LS-000057 | B31: 3215 ABBEYFIELD LN | C31: 1139 | D31: East Grid | E31: Duval | F31: 29221 | G31: =F31 -> 29221 | H31: JEA
A32: LS-000058 | B32: 5180 ABEL LN | C32: 1490 | D32: West Grid | E32: Duval | F32: 26753 | G32: =F32 -> 26753 | H32: JEA
A33: LS-000060 | B33: 12733 ABESS BV | C33: 1826 | D33: East Grid | E33: Duval | F33: 31778 | G33: =F33 -> 31778 | H33: JEA | I33: 2713621.3 | J33: 8000
A34: LS-000063 | B34: 8752 ACANTHUS DR | C34: 1564 | D34: West Grid | E34: Duval | F34: 25569 | G34: =F34 -> 25569 | H34: JEA | I34: 264041.89 | J34: 800
A35: LS-000067 | B35: 11933 ACOSTA RD | C35: 1968 | D35: South Grid | E35: Duval | F35: 29221 | G35: =F35 -> 29221 | H35: JEA
A36: LS-000069 | B36: 505 ADDOR LN | C36: 1369 | D36: West Grid | E36: Duval | F36: 33813 | G36: =F36 -> 33813 | H36: JEA
A37: LS-000070 | B37: 9374 ADELAID DR | C37: 2241 | D37: West Grid | E37: Duval | F37: 37117 | G37: =F37 -> 37117 | H37: JEA
A38: LS-000071 | B38: 2844 ADELE RD | C38: 2012 | D38: South Grid | E38: Duval | F38: 29221 | G38: =F38 -> 29221 | H38: JEA
A39: LS-000073 | B39: 13650 AEROSPACE WAY | C39: 89458 | D39: West Grid | E39: Duval | F39: 31048 | G39: =F39 -> 31048 | H39: JEA
A40: LS-000074 | B40: 125 AFTON LN | C40: 1963 | D40: St Johns Grid | E40: Duval | F40: 36039 | G40: =F40 -> 36039 | H40: JEA
...

Sheet reference-->

Sheet Major_CAR
B1: Asset | F1: Capacity Analysis | M1: 10-Year Forecast | S1: Projects | V1: Resiliency
A2: Basin | B2: CMMS | C2: Liftstation | D2: Class | F2: ADF | H2: PHF | I2: Capacity | K2: Utilization | M2: Growth | O2: ADF | P2: PHF | Q2: Utilization | S2: Related | T2: In-Service | V2: Num Pumps | W2: Station Bypass | X2: VFD Control | Y2: Pressure Gauge | Z2: Flow Meter
F3: (kGPD) | H3: (GPM) | I3: (GPM) | K3: (%) | M3: (%) | O3: (kGPD) | P3: (GPM) | Q3: (%)
A4: ARLINGTON EAST | B4: LS-001093 | C4: HOLIDAY RD S - 7834 | D4: 4 | F4: 1484.5624 | G4: 1 | H4: 2868.8733 | I4: 2800 | J4: 2 | K4: 1.0245976 | M4: 0.023739267 | N4: 1 | O4: =F4*(1+M4)^10 -> 1877.1202 | P4: =(18+SQRT(O4/100))/(4+SQRT(O4/100))*O4*1000/1440 -> 3493.7287 | Q4: =P4/I4 -> 1.2477602 | S4: 180-70 | T4: 2024 | V4: 3 | W4: 2 | X4: 1 | Y4: 1 | Z4: 0
A5: ARLINGTON EAST | B5: LS-000256 | C5: BAYMEADOWS RD - 9247 | D5: 3 | F5: 359.66475 | G5: 1 | H5: 842.7886 | I5: 700 | J5: 2 | K5: 1.2039837 | M5: 0.018404212 | N5: 1 | O5: =F5*(1+M5)^10 -> 431.61819 | P5: =(18+SQRT(O5/100))/(4+SQRT(O5/100))*O5*1000/1440 -> 990.19291 | Q5: =P5/I5 -> 1.4145613 | S5: 180-53 | T5: 2025 | V5: 2 | W5: 1 | X5: 0 | Y5: 1 | Z5: 0
A6: ARLINGTON EAST | B6: LS-000249 | C6: BAYLEAF RD - 8751 | D6: 3 | F6: 300.8379 | G6: 1 | H6: 718.95606 | I6: 800 | J6: 2 | K6: 0.89869508 | M6: 0.0056539838 | N6: 1 | O6: =F6*(1+M6)^10 -> 318.28658 | P6: =(18+SQRT(O6/100))/(4+SQRT(O6/100))*O6*1000/1440 -> 756.02914 | Q6: =P6/I6 -> 0.94503642 | S6: 180-54 | T6: 2026 | V6: 2 | W6: 1 | X6: 1 | Y6: 1 | Z6: 0
A7: ARLINGTON EAST | B7: LS-000495 | C7: BURNT MILL RD - 10828 | D7: 4 | F7: 1816.5661 | G7: 1 | H7: 3399.0986 | I7: 3100 | J7: 2 | K7: 1.0964834 | M7: 0.027202133 | N7: 1 | O7: =F7*(1+M7)^10 -> 2375.8025 | P7: =(18+SQRT(O7/100))/(4+SQRT(O7/100))*O7*1000/1440 -> 4252.692 | Q7: =P7/I7 -> 1.3718361 | S7: 175-66 | T7: 2028 | V7: 3 | W7: 1 | X7: 1 | Y7: 1 | Z7: 0
A8: ARLINGTON EAST | B8: LS-001813 | C8: PRINCETON SQUARE BV W - 8331 | D8: 3 | F8: 604.55655 | G8: 1 | H8: 1329.8541 | I8: 900 | J8: 2 | K8: 1.4776157 | M8: 0.00055848368 | N8: 1 | O8: =F8*(1+M8)^10 -> 607.9414 | P8: =(18+SQRT(O8/100))/(4+SQRT(O8/100))*O8*1000/1440 -> 1336.3269 | Q8: =P8/I8 -> 1.4848077 | S8: 180-57 | T8: 2028 | V8: 2 | W8: 1 | X8: 0 | Y8: 1 | Z8: 0
A9: ARLINGTON EAST | B9: LS-000018 | C9: A C SKINNER PY - 7200 | D9: 4 | F9: 1224.4444 | G9: 1 | H9: 2437.7194 | I9: 3770 | J9: 2 | K9: 0.64660993 | M9: 0.027669931 | N9: 1 | O9: =F9*(1+M9)^10 -> 1608.7019 | P9: =(18+SQRT(O9/100))/(4+SQRT(O9/100))*O9*1000/1440 -> 3069.5228 | Q9: =P9/I9 -> 0.81419703 | V9: 4 | W9: 2 | X9: 1 | Y9: 0 | Z9: 0
A10: ARLINGTON EAST | B10: LS-000060 | C10: ABESS BV - 12733 | D10: 4 | F10: 2713.6213 | G10: 4 | H10: 4749.2364 | I10: 8000 | J10: 2 | K10: 0.59365455 | M10: 0.01311607 | N10: 1 | O10: =F10*(1+M10)^10 -> 3091.3009 | P10: =(18+SQRT(O10/100))/(4+SQRT(O10/100))*O10*1000/1440 -> 5290.5109 | Q10: =P10/I10 -> 0.66131387 | V10: 4 | W10: 2 | X10: 0 | Y10: 1 | Z10: 1
A11: ARLINGTON EAST | B11: LS-000098 | C11: ALUMNI WY - 11220 | D11: 3 | F11: 170.8 | G11: 2 | H11: 431.51583 | I11: 533.66602 | J11: 1 | K11: 0.8085878 | M11: 0.0032458029 | N11: 1 | O11: =F11*(1+M11)^10 -> 176.42551 | P11: =(18+SQRT(O11/100))/(4+SQRT(O11/100))*O11*1000/1440 -> 444.43338 | Q11: =P11/I11 -> 0.8327931 | V11: 2 | W11: 1 | X11: 0 | Y11: 0 | Z11: 0
A12: ARLINGTON EAST | B12: LS-003974 | C12: BALBOA RD - 7106 | D12: 3 | F12: 268.01287 | G12: 1 | H12: 648.35704 | I12: 1360 | J12: 2 | K12: 0.47673311 | M12: 0.00042099215 | N12: 1 | O12: =F12*(1+M12)^10 -> 269.14332 | P12: =(18+SQRT(O12/100))/(4+SQRT(O12/100))*O12*1000/1440 -> 650.80792 | Q12: =P12/I12 -> 0.47853523 | V12: 3 | W12: 2 | X12: 0 | Y12: 1 | Z12: 0
A13: ARLINGTON EAST | B13: LS-000244 | C13: BAY HARBOUR DR - 4568 | D13: 3 | F13: 585.01531 | G13: 1 | H13: 1292.3654 | I13: 2400 | J13: 2 | K13: 0.5384856 | M13: 0.0019950733 | N13: 1 | O13: =F13*(1+M13)^10 -> 596.79214 | P13: =(18+SQRT(O13/100))/(4+SQRT(O13/100))*O13*1000/1440 -> 1314.9832 | Q13: =P13/I13 -> 0.54790965 | V13: 3 | W13: 1 | X13: 0 | Y13: 1 | Z13: 0
A14: ARLINGTON EAST | B14: LS-000254 | C14: BAYMEADOWS RD - 10702 | D14: 3 | F14: 357.75032 | G14: 1 | H14: 838.80861 | I14: 900 | J14: 2 | K14: 0.93200957 | M14: 0 | N14: 2 | O14: =F14*(1+M14)^10 -> 357.75032 | P14: =(18+SQRT(O14/100))/(4+SQRT(O14/100))*O14*1000/1440 -> 838.80861 | Q14: =P14/I14 -> 0.93200957 | V14: 2 | W14: 1 | X14: 0 | Y14: 1 | Z14: 0
A15: ARLINGTON EAST | B15: LS-000259 | C15: BAYMEADOWS RD E - 8036 | D15: 3 | F15: 312.79853 | G15: 1 | H15: 744.40127 | I15: 1458.6934 | J15: 1 | K15: 0.51032059 | M15: 0.036535777 | N15: 1 | O15: =F15*(1+M15)^10 -> 447.82432 | P15: =(18+SQRT(O15/100))/(4+SQRT(O15/100))*O15*1000/1440 -> 1022.8457 | Q15: =P15/I15 -> 0.70120681 | V15: 2 | W15: 1 | X15: 0 | Y15: 1 | Z15: 0
A16: ARLINGTON EAST | B16: LS-000370 | C16: BELFORT OAKS PL - 6868 | D16: 3 | F16: 233 | G16: 3 | H16: 571.70421 | I16: 1000 | J16: 2 | K16: 0.57170421 | M16: 0.039501976 | N16: 1 | O16: =F16*(1+M16)^10 -> 343.24887 | P16: =(18+SQRT(O16/100))/(4+SQRT(O16/100))*O16*1000/1440 -> 808.55592 | Q16: =P16/I16 -> 0.80855592 | V16: 2 | W16: 1 | X16: 0 | Y16: 1 | Z16: 0
A17: ARLINGTON EAST | B17: LS-000451 | C17: BOWLAN ST N - 544 | D17: 4 | F17: 295.08814 | G17: 1 | H17: 706.67229 | I17: 1200 | J17: 2 | K17: 0.58889357 | M17: 0.02252212 | N17: 1 | O17: =F17*(1+M17)^10 -> 368.70487 | P17: =(18+SQRT(O17/100))/(4+SQRT(O17/100))*O17*1000/1440 -> 861.53971 | Q17: =P17/I17 -> 0.71794976 | V17: 4 | W17: 1 | X17: 1 | Y17: 1 | Z17: 0
A18: ARLINGTON EAST | B18: BPS-004228 | C18: BRADLEY RD - 10477 | D18: 4 | F18: 12497.059 | G18: 1 | H18: 16682.926 | I18: 19500 | J18: 2 | K18: 0.85553467 | M18: 0.0085762833 | N18: 4 | O18: =F18*(1+M18)^10 -> 13611.166 | P18: =(18+SQRT(O18/100))/(4+SQRT(O18/100))*O18*1000/1440 -> 17898.831 | Q18: =P18/I18 -> 0.91788878 | V18: 6 | W18: 2 | X18: 1 | Y18: 1 | Z18: 0
A19: ARLINGTON EAST | B19: LS-000536 | C19: CEDAR ISLAND DR - 14600 | D19: 3 | F19: 269.68929 | G19: 1 | H19: 651.99108 | I19: 1130 | J19: 2 | K19: 0.57698326 | M19: 0.0062091023 | N19: 1 | O19: =F19*(1+M19)^10 -> 286.91029 | P19: =(18+SQRT(O19/100))/(4+SQRT(O19/100))*O19*1000/1440 -> 689.14186 | Q19: =P19/I19 -> 0.60986005 | V19: 2 | W19: 1 | X19: 1 | Y19: 1 | Z19: 0
A20: ARLINGTON EAST | B20: LS-000540 | C20: CENTRAL PY - 11550 | D20: 3 | F20: 199.869 | G20: 1 | H20: 497.7304 | I20: 1026.6982 | J20: 1 | K20: 0.48478746 | M20: 0.0062275976 | N20: 1 | O20: =F20*(1+M20)^10 -> 212.67071 | P20: =(18+SQRT(O20/100))/(4+SQRT(O20/100))*O20*1000/1440 -> 526.49148 | Q20: =P20/I20 -> 0.51280064 | V20: 2 | W20: 1 | X20: 0 | Y20: 0 | Z20: 0
... A26: ARLINGTON EAST | B26: LS-001187 | C26: FIRST COAST TECH PY - 5192 | D26: 3 | F26: 71.811324 | G26: 2 | H26: 193.8974 | I26: 497.69927 | J26: 1 | K26: 0.38958748 | M26: 0.05 | N26: 2 | O26: =F26*(1+M26)^10 -> 116.97308 | P26: =(18+SQRT(O26/100))/(4+SQRT(O26/100))*O26*1000/1440 -> 305.02922 | Q26: =P26/I26 -> 0.61287858 | V26: 2 | W26: 1 | X26: 0 | Y26: 1 | Z26: 0
A27: ARLINGTON EAST | B27: LS-000915 | C27: FT CAROLINE RD - 10797 | D27: 3 | F27: 1259 | G27: 3 | H27: 2495.9126 | I27: 2500 | J27: 2 | K27: 0.99836505 | M27: 0.002035898 | N27: 1 | O27: =F27*(1+M27)^10 -> 1284.8681 | P27: =(18+SQRT(O27/100))/(4+SQRT(O27/100))*O27*1000/1440 -> 2539.2816 | Q27: =P27/I27 -> 1.0157127 | S27: * | V27: 2 | W27: 2 | X27: 0 | Y27: 1 | Z27: 0
A28: ARLINGTON EAST | B28: LS-000932 | C28: GATE PY N - 9898 | D28: 4 | F28: 487.7684 | G28: 1 | H28: 1102.5448 | I28: 2000 | J28: 3 | K28: 0.55127239 | M28: 0.012877142 | N28: 1 | O28: =F28*(1+M28)^10 -> 554.34657 | P28: =(18+SQRT(O28/100))/(4+SQRT(O28/100))*O28*1000/1440 -> 1233.1047 | Q28: =P28/I28 -> 0.61655237 | V28: 3 | W28: 1 | X28: 1 | Y28: 1 | Z28: 0
A29: ARLINGTON EAST | B29: LS-000956 | C29: GLEN KERN PY - 12858 | D29: 3 | F29: 119.43772 | G29: 1 | H29: 310.94765 | I29: 1200 | J29: 2 | K29: 0.25912304 | M29: 0.032279624 | N29: 3 | O29: =F29*(1+M29)^10 -> 164.10245 | P29: =(18+SQRT(O29/100))/(4+SQRT(O29/100))*O29*1000/1440 -> 416.06815 | Q29: =P29/I29 -> 0.34672346 | V29: 2 | W29: 1 | X29: 0 | Y29: 1 | Z29: 0
A30: ARLINGTON EAST | B30: LS-000997 | C30: GROVE PARK BV - 487 | D30: 3 | F30: 423.22649 | G30: 1 | H30: 973.20962 | I30: 1400 | J30: 3 | K30: 0.69514973 | M30: 0.034387391 | N30: 1 | O30: =F30*(1+M30)^10 -> 593.47854 | P30: =(18+SQRT(O30/100))/(4+SQRT(O30/100))*O30*1000/1440 -> 1308.6269 | Q30: =P30/I30 -> 0.93473351 | V30: 2 | W30: 2 | X30: 0 | Y30: 1 | Z30: 0
A31: ARLINGTON EAST | B31: LS-001089 | C31: HODGES BV - 1705 | D31: 4 | F31: 948.16813 | G31: 1 | H31: 1960.6109 | I31: 3200 | J31: 2 | K31: 0.61269092 | M31: 0.0043491527 | N31: 1 | O31: =F31*(1+M31)^10 -> 990.2219 | P31: =(18+SQRT(O31/100))/(4+SQRT(O31/100))*O31*1000/1440 -> 2034.7165 | Q31: =P31/I31 -> 0.6358489 | V31: 2 | W31: 2 | X31: 0 | Y31: 1 | Z31: 0
A32: ARLINGTON EAST | B32: LS-001114 | C32: HUFFMAN BV - 2798 | D32: 4 | F32: 3465.9897 | G32: 1 | H32: 5815.0709 | I32: 7000 | J32: 2 | K32: =H32/I32 -> 0.83072441 | M32: 0.021296507 | N32: 1 | O32: =F32*(1+M32)^10 -> 4279.034 | P32: =(18+SQRT(O32/100))/(4+SQRT(O32/100))*O32*1000/1440 -> 6918.0472 | Q32: =P32/I32 -> 0.98829245 | S32: * | V32: 3 | W32: 2 | X32: 1 | Y32: 1 | Z32: 0
A33: ARLINGTON EAST | B33: LS-001185 | C33: KERN BV S - 3431 | D33: 3 | F33: 263 | G33: 3 | H33: 637.4714 | I33: 1547.9593 | J33: 1 | K33: 0.41181405 | M33: 0.014887645 | N33: 1 | O33: =F33*(1+M33)^10 -> 304.88454 | P33: =(18+SQRT(O33/100))/(4+SQRT(O33/100))*O33*1000/1440 -> 727.58103 | Q33: =P33/I33 -> 0.47002594 | V33: 2 | W33: 1 | X33: 0 | Y33: 1 | Z33: 0
A34: ARLINGTON EAST | B34: LS-001207 | C34: LA VISTA CR - 4181 | D34: 3 | F34: 231.68027 | G34: 2 | H34: 568.78557 | I34: 1048.3784 | J34: 1 | K34: 0.54253843 | M34: 0.00015895064 | N34: 1 | O34: =F34*(1+M34)^10 -> 232.0488 | P34: =(18+SQRT(O34/100))/(4+SQRT(O34/100))*O34*1000/1440 -> 569.6008 | Q34: =P34/I34 -> 0.54331604 | V34: 2 | W34: 1 | X34: 0 | Y34: 1 | Z34: 0
A35: ARLINGTON EAST | B35: LS-001459 | C35: MILL CREEK RD - 1030 | D35: 3 | F35: 184.3553 | G35: 1 | H35: 462.55577 | I35: 1490 | J35: 2 | K35: 0.31044011 | M35: 0.066357065 | N35: 1 | O35: =F35*(1+M35)^10 -> 350.49525 | P35: =(18+SQRT(O35/100))/(4+SQRT(O35/100))*O35*1000/1440 -> 823.69658 | Q35: =P35/I35 -> 0.5528165 | V35: 3 | W35: 1 | X35: 0 | Y35: 1 | Z35: 0
A36: ARLINGTON EAST | B36: LS-001851 | C36: REEDY BRANCH DR - 8614 | D36: 4 | F36: 40.660666 | G36: 2 | H36: 113.47617 | I36: 2221.0143 | J36: 1 | K36: 0.051092049 | M36: 0 | N36: 3 | O36: =F36*(1+M36)^10 -> 40.660666 | P36: =(18+SQRT(O36/100))/(4+SQRT(O36/100))*O36*1000/1440 -> 113.47617 | Q36: =P36/I36 -> 0.051092049 | V36: 2 | W36: 1 | X36: 0 | Y36: 1 | Z36: 0
A37: ARLINGTON EAST | B37: LS-001933 | C37: RYAR RD - 1531 | D37: 4 | F37: 382.72639 | G37: 1 | H37: 890.48654 | I37: 1750 | J37: 2 | K37: 0.50884945 | M37: 0.043661692 | N37: 1 | O37: =F37*(1+M37)^10 -> 586.79423 | P37: =(18+SQRT(O37/100))/(4+SQRT(O37/100))*O37*1000/1440 -> 1295.7867 | Q37: =P37/I37 -> 0.74044956 | V37: 3 | W37: 1 | X37: 0 | Y37: 0 | Z37: 0
A38: ARLINGTON EAST | B38: BPS-001950 | C38: SAN CLERC RD - 4241 | D38: 4 | F38: 932 | G38: 3 | H38: 1931.9637 | I38: 3040 | J38: 2 | K38: 0.63551436 | M38: 0.002894213 | N38: 3 | O38: =F38*(1+M38)^10 -> 959.3281 | P38: =(18+SQRT(O38/100))/(4+SQRT(O38/100))*O38*1000/1440 -> 1980.3333 | Q38: =P38/I38 -> 0.65142544 | V38: 3 | W38: 1 | X38: 1 | Y38: 1 | Z38: 0
A39: ARLINGTON EAST | B39: LS-002007 | C39: SAN PABLO RD S - 4950 | D39: 3 | F39: 62.38835 | G39: 2 | H39: 169.95797 | I39: 1061 | J39: 2 | K39: 0.16018659 | M39: 0.013307063 | N39: 1 | O39: =F39*(1+M39)^10 -> 71.205608 | P39: =(18+SQRT(O39/100))/(4+SQRT(O39/100))*O39*1000/1440 -> 192.36751 | Q39: =P39/I39 -> 0.18130773 | V39: 2 | W39: 1 | X39: 0 | Y39: 1 | Z39: 0
A40: ARLINGTON EAST | B40: LS-002104 | C40: SOUTHSIDE BV - 7133 | D40: 4 | F40: 1037.9629 | G40: 1 | H40: 2118.1579 | I40: 3150 | J40: 3 | K40: 0.67243109 | M40: 0.03 | N40: 2 | O40: =F40*(1+M40)^10 -> 1394.9353 | P40: =(18+SQRT(O40/100))/(4+SQRT(O40/100))*O40*1000/1440 -> 2722.0439 | Q40: =P40/I40 -> 0.86414091 | V40: 3 | W40: 2 | X40: 1 | Y40: 1 | Z40: 0
A41: ARLINGTON EAST | B41: LS-002112 | C41: SOUTHSIDE BV - 9041 | D41: 3 | F41: 320.53673 | G41: 1 | H41: 760.78818 | I41: 900 | J41: 2 | K41: 0.84532021 | M41: 0.0082285439 | N41: 1 | O41: =F41*(1+M41)^10 -> 347.91062 | P41: =(18+SQRT(O41/100))/(4+SQRT(O41/100))*O41*1000/1440 -> 818.30164 | Q41: =P41/I41 -> 0.90922404 | V41: 3 | W41: 1 | X41: 0 | Y41: 1 | Z41: 0
A42: ARLINGTON EAST | B42: LS-002243 | C42: SUTTON PARK DR N - 13825 | D42: 3 | F42: 696.15003 | G42: 1 | H42: 1502.9691 | I42: 1700 | J42: 3 | K42: 0.88409948 | M42: 0.0028394635 | N42: 1 | O42: =F42*(1+M42)^10 -> 716.17145 | P42: =(18+SQRT(O42/100))/(4+SQRT(O42/100))*O42*1000/1440 -> 1540.2763 | Q42: =P42/I42 -> 0.90604488 | V42: 3 | W42: 1 | X42: 0 | Y42: 0 | Z42: 0
A43: ARLINGTON EAST | B43: LS-002289 | C43: TOUCHTON RD - 8362 | D43: 3 | F43: 166.79392 | G43: 2 | H43: 422.28503 | I43: 2375.2079 | J43: 1 | K43: 0.17778866 | M43: 0.0062432867 | N43: 1 | O43: =F43*(1+M43)^10 -> 177.50483 | P43: =(18+SQRT(O43/100))/(4+SQRT(O43/100))*O43*1000/1440 -> 446.9059 | Q43: =P43/I43 -> 0.18815443 | V43: 2 | W43: 1 | X43: 0 | Y43: 1 | Z43: 0
A44: ARLINGTON EAST | B44: LS-002294 | C44: TOWN CENTER PY - 4522 | D44: 4 | F44: 462.27551 | G44: 1 | H44: 1051.8055 | I44: 1500 | J44: 2 | K44: =H44/I44 -> 0.70120364 | M44: 0.040527624 | N44: 1 | O44: =F44*(1+M44)^10 -> 687.76019 | P44: =(18+SQRT(O44/100))/(4+SQRT(O44/100))*O44*1000/1440 -> 1487.2811 | Q44: =P44/I44 -> 0.99152077 | S44: * | V44: 3 | W44: 1 | X44: 0 | Y44: 1 | Z44: 0
A45: ARLINGTON EAST | B45: LS-002307 | C45: TRESCA RD - 420 | D45: 3 | F45: 403.02978 | G45: 1 | H45: 932.11747 | I45: 1930 | J45: 2 | K45: 0.48296242 | M45: 0.00072549187 | N45: 1 | O45: =F45*(1+M45)^10 -> 405.96329 | P45: =(18+SQRT(O45/100))/(4+SQRT(O45/100))*O45*1000/1440 -> 938.10545 | Q45: =P45/I45 -> 0.486065 | V45: 2 | W45: 1 | X45: 0 | Y45: 1 | Z45: 0
...

Sheet piwebapi_90d
A1: cmms | B1: adf_kGPD | C1: phf_gpm
A2: LS-000550 | B2: 131.29719 | C2: 252.0902
A3: LS-002144 | B3: 0.11117275 | C3: 13.941855
A4: LS-000813 | B4: 0.15356611 | C4: 227.91013
A5: LS-003704 | B5: 0.20328535 | C5: 58.329711
A6: LS-002143 | B6: 0.24837129 | C6: 54.101283
A7: LS-001564 | B7: 0.27064438 | C7: 15.462294
A8: LS-000656 | B8: 0.29507934 | C8: 7.3561859
A9: LS-004101 | B9: 0.37024167 | C9: 11.330883
A10: LS-001870 | B10: 0.39873164 | C10: 99.94141
A11: LS-001462 | B11: 0.42895099 | C11: 98.317884
A12: LS-003714 | B12: 0.4311926 | C12: 376.56859
A13: LS-004060 | B13: 0.51633584 | C13: 164.28453
... A1471: LS-001423 | B1471: 2310.4918 | C1471: 1643.761
